Workbook

Sheet All Facts
A1: Brand | B1: Name | C1: Servings Per Container | D1: Serving Size | E1: Serving Size Unit | F1: Serving Size Grams | G1: Calories | H1: Total Fat Grams | I1: Total Carb Grams | J1: Protein Grams | K1: Saturated Fat Grams | L1: Polysaturated Fat Grams | M1: Monosaturated Fat Grams | N1: Cholesterol mg | O1: Sodium mg | P1: Vitamin D mcg | Q1: Calcium mg | R1: Iron mg | S1: Potassium mg | T1: Dietary Fiber grams | U1: Total Sugars Grams | V1: Vitamin C mg | W1: Vitamin B6 mg | X1: Folic Acid mcg | Y1: Niacin mg | Z1: Thiamin mg
A2: Harris Teeter | B2: Atlantic Skin-On Farm Raised Salmon | C2: 1 | D2: 1 | E2: Fillet | F2: =113*2.5 -> 282.5 | G2: =260*2.5 -> 650 | H2: =19*2.5 -> 47.5 | I2: 0 | J2: =23*2.5 -> 57.5 | K2: =2.5*2.5 -> 6.25 | N2: =65*2.5 -> 162.5 | O2: =35*2.5 -> 87.5 | P2: =8*2.5 -> 20 | Q2: =52*2.5 -> 130 | S2: =376*2.5 -> 940
A3: Harris Teeter | B3: Chicken Breast | C3: 1 | D3: 4 | E3: ounces | F3: 112 | G3: 110 | H3: 1 | I3: 0 | J3: 25 | N3: 80 | O3: 75 | R3: 0.36
A4: Harris Teeter | B4: Fishermans Market Tail On Peeled & Deveined Cooked Shrimp | C4: 4 | D4: 3 | E4: ounces | F4: 85 | G4: 45 | H4: 0 | I4: 0 | J4: 11 | N4: 120 | O4: 400
A5: Harris Teeter | B5: Pre-Washed Russet Potatoes | C5: 15.3 | D5: 1 | E5: Potato | F5: 148 | G5: 110 | I5: 26 | J5: 3 | Q5: 20 | R5: 1.1 | S5: 620 | T5: 2 | U5: 1 | V5: 26 | W5: 0.2
A6: Harris Teeter | B6: Peanut Butter | C6: 35 | D6: 2 | E6: Tbsp | F6: 32 | G6: 180 | H6: 15 | I6: 7 | J6: 7 | K6: 2.5 | O6: 150 | Q6: 30 | R6: 1 | S6: 210 | T6: 2 | U6: 4
A7: Harris Teeter | B7: Lower Sodium Bacon | C7: 7 | D7: 2 | E7: slices | F7: 15 | G7: 80 | H7: 6 | I7: 0 | J7: 4 | K7: 2.5 | N7: 15 | O7: 180 | R7: 0.36
A8: Harris Teeter | B8: Eye Round Steak | C8: 1 | D8: 4 | E8: ounces | F8: 112 | G8: 151 | H8: 7 | I8: 0 | J8: 22 | R8: 1.44
A9: Harris Teeter | B9: Grade A Large Egg | C9: 12 | D9: 1 | E9: egg | F9: 50 | G9: 70 | H9: 5 | I9: 0 | J9: 6 | K9: 1.5 | N9: 185 | O9: 70 | P9: 1 | Q9: 30 | R9: 0.9
A10: Harris Teeter | B10: All Purpose Flour | C10: 30 | D10: 0.25 | E10: cup | F10: 30 | G10: 110 | H10: 0 | I10: 23 | J10: 2 | R10: 1.3 | S10: 30 | X10: 50 | Y10: 1.4 | Z10: 0.22
A11: Harris Teeter | B11: Colby Jack Cheese | C11: 8 | D11: 6 | E11: cubes | F11: 28 | G11: 110 | H11: 9 | I11: 1 | J11: 7 | K11: 5 | N11: 30 | O11: 170 | P11: 0.2 | Q11: 200 | R11: 0.2 | S11: 30
D17: =F11/D11 -> 4.6666667

Sheet Recipie
A1: Name | B1: Ingredient | C1: Grams Selected | D1: ='All Facts'!G1 -> Calories | E1: ='All Facts'!H1 -> Total Fat Grams | F1: ='All Facts'!I1 -> Total Carb Grams | G1: ='All Facts'!J1 -> Protein Grams | H1: ='All Facts'!K1 -> Saturated Fat Grams | I1: ='All Facts'!L1 -> Polysaturated Fat Grams | J1: ='All Facts'!M1 -> Monosaturated Fat Grams | K1: ='All Facts'!N1 -> Cholesterol mg | ... W1: ='All Facts'!Z1 -> Thiamin mg | AA1: Ratios | AC1: Grams | AE1: Grams
A2: Chicken Nuggets | B2: Grade A Large Egg | C2: =MROUND(AC2/AE2*C4,AC2) -> 100 | D2: =INDEX('All Facts'!G:G,MATCH(Recipie!$B2,'All Facts'!$B:$B,0),1)/INDEX('All Facts'!$F:$F,MATCH(Recipie!$B2,'All Facts'!$B:$B,0),1)*$C2 -> 140 | E2: =INDEX('All Facts'!H:H,MATCH(Recipie!$B2,'All Facts'!$B:$B,0),1)/INDEX('All Facts'!$F:$F,MATCH(Recipie!$B2,'All Facts'!$B:$B,0),1)*$C2 -> 10 | F2: =INDEX('All Facts'!I:I,MATCH(Recipie!$B2,'All Facts'!$B:$B,0),1)/INDEX('All Facts'!$F:$F,MATCH(Recipie!$B2,'All Facts'!$B:$B,0),1)*$C2 -> 0 | G2: =INDEX('All Facts'!J:J,MATCH(Recipie!$B2,'All Facts'!$B:$B,0),1)/INDEX('All Facts'!$F:$F,MATCH(Recipie!$B2,'All Facts'!$B:$B,0),1)*$C2 -> 12 | H2: =INDEX('All Facts'!K:K,MATCH(Recipie!$B2,'All Facts'!$B:$B,0),1)/INDEX('All Facts'!$F:$F,MATCH(Recipie!$B2,'All Facts'!$B:$B,0),1)*$C2 -> 3 | I2: =INDEX('All Facts'!L:L,MATCH(Recipie!$B2,'All Facts'!$B:$B,0),1)/INDEX('All Facts'!$F:$F,MATCH(Recipie!$B2,'All Facts'!$B:$B,0),1)*$C2 -> 0 | J2: =INDEX('All Facts'!M:M,MATCH(Recipie!$B2,'All Facts'!$B:$B,0),1)/INDEX('All Facts'!$F:$F,MATCH(Recipie!$B2,'All Facts'!$B:$B,0),1)*$C2 -> 0 | K2: =INDEX('All Facts'!N:N,MATCH(Recipie!$B2,'All Facts'!$B:$B,0),1)/INDEX('All Facts'!$F:$F,MATCH(Recipie!$B2,'All Facts'!$B:$B,0),1)*$C2 -> 370 | L2: =INDEX('All Facts'!O:O,MATCH(Recipie!$B2,'All Facts'!$B:$B,0),1)/INDEX('All Facts'!$F:$F,MATCH(Recipie!$B2,'All Facts'!$B:$B,0),1)*$C2 -> 140 | M2: =INDEX('All Facts'!P:P,MATCH(Recipie!$B2,'All Facts'!$B:$B,0),1)/INDEX('All Facts'!$F:$F,MATCH(Recipie!$B2,'All Facts'!$B:$B,0),1)*$C2 -> 2 | N2: =INDEX('All Facts'!Q:Q,MATCH(Recipie!$B2,'All Facts'!$B:$B,0),1)/INDEX('All Facts'!$F:$F,MATCH(Recipie!$B2,'All Facts'!$B:$B,0),1)*$C2 -> 60 | O2: =INDEX('All Facts'!R:R,MATCH(Recipie!$B2,'All Facts'!$B:$B,0),1)/INDEX('All Facts'!$F:$F,MATCH(Recipie!$B2,'All Facts'!$B:$B,0),1)*$C2 -> 1.8 | P2: =INDEX('All Facts'!S:S,MATCH(Recipie!$B2,'All Facts'!$B:$B,0),1)/INDEX('All Facts'!$F:$F,MATCH(Recipie!$B2,'All Facts'!$B:$B,0),1)*$C2 -> 0 | Q2: =INDEX('All Facts'!T:T,MATCH(Recipie!$B2,'All Facts'!$B:$B,0),1)/INDEX('All Facts'!$F:$F,MATCH(Recipie!$B2,'All Facts'!$B:$B,0),1)*$C2 -> 0 | R2: =INDEX('All Facts'!U:U,MATCH(Recipie!$B2,'All Facts'!$B:$B,0),1)/INDEX('All Facts'!$F:$F,MATCH(Recipie!$B2,'All Facts'!$B:$B,0),1)*$C2 -> 0 | S2: =INDEX('All Facts'!V:V,MATCH(Recipie!$B2,'All Facts'!$B:$B,0),1)/INDEX('All Facts'!$F:$F,MATCH(Recipie!$B2,'All Facts'!$B:$B,0),1)*$C2 -> 0 | T2: =INDEX('All Facts'!W:W,MATCH(Recipie!$B2,'All Facts'!$B:$B,0),1)/INDEX('All Facts'!$F:$F,MATCH(Recipie!$B2,'All Facts'!$B:$B,0),1)*$C2 -> 0 | U2: =INDEX('All Facts'!X:X,MATCH(Recipie!$B2,'All Facts'!$B:$B,0),1)/INDEX('All Facts'!$F:$F,MATCH(Recipie!$B2,'All Facts'!$B:$B,0),1)*$C2 -> 0 | V2: =INDEX('All Facts'!Y:Y,MATCH(Recipie!$B2,'All Facts'!$B:$B,0),1)/INDEX('All Facts'!$F:$F,MATCH(Recipie!$B2,'All Facts'!$B:$B,0),1)*$C2 -> 0 | W2: =INDEX('All Facts'!Z:Z,MATCH(Recipie!$B2,'All Facts'!$B:$B,0),1)/INDEX('All Facts'!$F:$F,MATCH(Recipie!$B2,'All Facts'!$B:$B,0),1)*$C2 -> 0 | AA2: Chicken Nuggets | AB2: Grade A Large Egg | AC2: 50 | AD2: Chicken Breast | AE2: 450
A3: Chicken Nuggets | B3: All Purpose Flour | C3: =AC3/AE3*C4 -> 72.546508 | D3: =INDEX('All Facts'!G:G,MATCH(Recipie!$B3,'All Facts'!$B:$B,0),1)/INDEX('All Facts'!$F:$F,MATCH(Recipie!$B3,'All Facts'!$B:$B,0),1)*$C3 -> 266.00386 | E3: =INDEX('All Facts'!H:H,MATCH(Recipie!$B3,'All Facts'!$B:$B,0),1)/INDEX('All Facts'!$F:$F,MATCH(Recipie!$B3,'All Facts'!$B:$B,0),1)*$C3 -> 0 | F3: =INDEX('All Facts'!I:I,MATCH(Recipie!$B3,'All Facts'!$B:$B,0),1)/INDEX('All Facts'!$F:$F,MATCH(Recipie!$B3,'All Facts'!$B:$B,0),1)*$C3 -> 55.618989 | G3: =INDEX('All Facts'!J:J,MATCH(Recipie!$B3,'All Facts'!$B:$B,0),1)/INDEX('All Facts'!$F:$F,MATCH(Recipie!$B3,'All Facts'!$B:$B,0),1)*$C3 -> 4.8364338 | H3: =INDEX('All Facts'!K:K,MATCH(Recipie!$B3,'All Facts'!$B:$B,0),1)/INDEX('All Facts'!$F:$F,MATCH(Recipie!$B3,'All Facts'!$B:$B,0),1)*$C3 -> 0 | I3: =INDEX('All Facts'!L:L,MATCH(Recipie!$B3,'All Facts'!$B:$B,0),1)/INDEX('All Facts'!$F:$F,MATCH(Recipie!$B3,'All Facts'!$B:$B,0),1)*$C3 -> 0 | J3: =INDEX('All Facts'!M:M,MATCH(Recipie!$B3,'All Facts'!$B:$B,0),1)/INDEX('All Facts'!$F:$F,MATCH(Recipie!$B3,'All Facts'!$B:$B,0),1)*$C3 -> 0 | K3: =INDEX('All Facts'!N:N,MATCH(Recipie!$B3,'All Facts'!$B:$B,0),1)/INDEX('All Facts'!$F:$F,MATCH(Recipie!$B3,'All Facts'!$B:$B,0),1)*$C3 -> 0 | L3: =INDEX('All Facts'!O:O,MATCH(Recipie!$B3,'All Facts'!$B:$B,0),1)/INDEX('All Facts'!$F:$F,MATCH(Recipie!$B3,'All Facts'!$B:$B,0),1)*$C3 -> 0 | M3: =INDEX('All Facts'!P:P,MATCH(Recipie!$B3,'All Facts'!$B:$B,0),1)/INDEX('All Facts'!$F:$F,MATCH(Recipie!$B3,'All Facts'!$B:$B,0),1)*$C3 -> 0 | N3: =INDEX('All Facts'!Q:Q,MATCH(Recipie!$B3,'All Facts'!$B:$B,0),1)/INDEX('All Facts'!$F:$F,MATCH(Recipie!$B3,'All Facts'!$B:$B,0),1)*$C3 -> 0 | O3: =INDEX('All Facts'!R:R,MATCH(Recipie!$B3,'All Facts'!$B:$B,0),1)/INDEX('All Facts'!$F:$F,MATCH(Recipie!$B3,'All Facts'!$B:$B,0),1)*$C3 -> 3.143682 | P3: =INDEX('All Facts'!S:S,MATCH(Recipie!$B3,'All Facts'!$B:$B,0),1)/INDEX('All Facts'!$F:$F,MATCH(Recipie!$B3,'All Facts'!$B:$B,0),1)*$C3 -> 72.546508 | Q3: =INDEX('All Facts'!T:T,MATCH(Recipie!$B3,'All Facts'!$B:$B,0),1)/INDEX('All Facts'!$F:$F,MATCH(Recipie!$B3,'All Facts'!$B:$B,0),1)*$C3 -> 0 | R3: =INDEX('All Facts'!U:U,MATCH(Recipie!$B3,'All Facts'!$B:$B,0),1)/INDEX('All Facts'!$F:$F,MATCH(Recipie!$B3,'All Facts'!$B:$B,0),1)*$C3 -> 0 | S3: =INDEX('All Facts'!V:V,MATCH(Recipie!$B3,'All Facts'!$B:$B,0),1)/INDEX('All Facts'!$F:$F,MATCH(Recipie!$B3,'All Facts'!$B:$B,0),1)*$C3 -> 0 | T3: =INDEX('All Facts'!W:W,MATCH(Recipie!$B3,'All Facts'!$B:$B,0),1)/INDEX('All Facts'!$F:$F,MATCH(Recipie!$B3,'All Facts'!$B:$B,0),1)*$C3 -> 0 | U3: =INDEX('All Facts'!X:X,MATCH(Recipie!$B3,'All Facts'!$B:$B,0),1)/INDEX('All Facts'!$F:$F,MATCH(Recipie!$B3,'All Facts'!$B:$B,0),1)*$C3 -> 120.91085 | V3: =INDEX('All Facts'!Y:Y,MATCH(Recipie!$B3,'All Facts'!$B:$B,0),1)/INDEX('All Facts'!$F:$F,MATCH(Recipie!$B3,'All Facts'!$B:$B,0),1)*$C3 -> 3.3855037 | W3: =INDEX('All Facts'!Z:Z,MATCH(Recipie!$B3,'All Facts'!$B:$B,0),1)/INDEX('All Facts'!$F:$F,MATCH(Recipie!$B3,'All Facts'!$B:$B,0),1)*$C3 -> 0.53200772 | AA3: Chicken Nuggets | AB3: All Purpose Flour | AC3: 60 | AD3: Chicken Breast | AE3: 560
A4: Chicken Nuggets | B4: Chicken Breast | C4: =Solver!C12 -> 677.10074 | D4: =INDEX('All Facts'!G:G,MATCH(Recipie!$B4,'All Facts'!$B:$B,0),1)/INDEX('All Facts'!$F:$F,MATCH(Recipie!$B4,'All Facts'!$B:$B,0),1)*$C4 -> 665.00965 | E4: =INDEX('All Facts'!H:H,MATCH(Recipie!$B4,'All Facts'!$B:$B,0),1)/INDEX('All Facts'!$F:$F,MATCH(Recipie!$B4,'All Facts'!$B:$B,0),1)*$C4 -> 6.0455423 | F4: =INDEX('All Facts'!I:I,MATCH(Recipie!$B4,'All Facts'!$B:$B,0),1)/INDEX('All Facts'!$F:$F,MATCH(Recipie!$B4,'All Facts'!$B:$B,0),1)*$C4 -> 0 | G4: =INDEX('All Facts'!J:J,MATCH(Recipie!$B4,'All Facts'!$B:$B,0),1)/INDEX('All Facts'!$F:$F,MATCH(Recipie!$B4,'All Facts'!$B:$B,0),1)*$C4 -> 151.13856 | H4: =INDEX('All Facts'!K:K,MATCH(Recipie!$B4,'All Facts'!$B:$B,0),1)/INDEX('All Facts'!$F:$F,MATCH(Recipie!$B4,'All Facts'!$B:$B,0),1)*$C4 -> 0 | I4: =INDEX('All Facts'!L:L,MATCH(Recipie!$B4,'All Facts'!$B:$B,0),1)/INDEX('All Facts'!$F:$F,MATCH(Recipie!$B4,'All Facts'!$B:$B,0),1)*$C4 -> 0 | J4: =INDEX('All Facts'!M:M,MATCH(Recipie!$B4,'All Facts'!$B:$B,0),1)/INDEX('All Facts'!$F:$F,MATCH(Recipie!$B4,'All Facts'!$B:$B,0),1)*$C4 -> 0 | K4: =INDEX('All Facts'!N:N,MATCH(Recipie!$B4,'All Facts'!$B:$B,0),1)/INDEX('All Facts'!$F:$F,MATCH(Recipie!$B4,'All Facts'!$B:$B,0),1)*$C4 -> 483.64338 | L4: =INDEX('All Facts'!O:O,MATCH(Recipie!$B4,'All Facts'!$B:$B,0),1)/INDEX('All Facts'!$F:$F,MATCH(Recipie!$B4,'All Facts'!$B:$B,0),1)*$C4 -> 453.41567 | M4: =INDEX('All Facts'!P:P,MATCH(Recipie!$B4,'All Facts'!$B:$B,0),1)/INDEX('All Facts'!$F:$F,MATCH(Recipie!$B4,'All Facts'!$B:$B,0),1)*$C4 -> 0 | N4: =INDEX('All Facts'!Q:Q,MATCH(Recipie!$B4,'All Facts'!$B:$B,0),1)/INDEX('All Facts'!$F:$F,MATCH(Recipie!$B4,'All Facts'!$B:$B,0),1)*$C4 -> 0 | O4: =INDEX('All Facts'!R:R,MATCH(Recipie!$B4,'All Facts'!$B:$B,0),1)/INDEX('All Facts'!$F:$F,MATCH(Recipie!$B4,'All Facts'!$B:$B,0),1)*$C4 -> 2.1763952 | P4: =INDEX('All Facts'!S:S,MATCH(Recipie!$B4,'All Facts'!$B:$B,0),1)/INDEX('All Facts'!$F:$F,MATCH(Recipie!$B4,'All Facts'!$B:$B,0),1)*$C4 -> 0 | Q4: =INDEX('All Facts'!T:T,MATCH(Recipie!$B4,'All Facts'!$B:$B,0),1)/INDEX('All Facts'!$F:$F,MATCH(Recipie!$B4,'All Facts'!$B:$B,0),1)*$C4 -> 0 | R4: =INDEX('All Facts'!U:U,MATCH(Recipie!$B4,'All Facts'!$B:$B,0),1)/INDEX('All Facts'!$F:$F,MATCH(Recipie!$B4,'All Facts'!$B:$B,0),1)*$C4 -> 0 | S4: =INDEX('All Facts'!V:V,MATCH(Recipie!$B4,'All Facts'!$B:$B,0),1)/INDEX('All Facts'!$F:$F,MATCH(Recipie!$B4,'All Facts'!$B:$B,0),1)*$C4 -> 0 | T4: =INDEX('All Facts'!W:W,MATCH(Recipie!$B4,'All Facts'!$B:$B,0),1)/INDEX('All Facts'!$F:$F,MATCH(Recipie!$B4,'All Facts'!$B:$B,0),1)*$C4 -> 0 | U4: =INDEX('All Facts'!X:X,MATCH(Recipie!$B4,'All Facts'!$B:$B,0),1)/INDEX('All Facts'!$F:$F,MATCH(Recipie!$B4,'All Facts'!$B:$B,0),1)*$C4 -> 0 | V4: =INDEX('All Facts'!Y:Y,MATCH(Recipie!$B4,'All Facts'!$B:$B,0),1)/INDEX('All Facts'!$F:$F,MATCH(Recipie!$B4,'All Facts'!$B:$B,0),1)*$C4 -> 0 | W4: =INDEX('All Facts'!Z:Z,MATCH(Recipie!$B4,'All Facts'!$B:$B,0),1)/INDEX('All Facts'!$F:$F,MATCH(Recipie!$B4,'All Facts'!$B:$B,0),1)*$C4 -> 0 | AA4: Fried Shrimp | AB4: Grade A Large Egg | AC4: 50 | AD4: Fishermans Market Tail On Peeled & Deveined Cooked Shrimp | AE4: 450
A5: Chicken Nuggets | B5: Total | C5: =SUM(C2:C4) -> 849.64724 | D5: =SUM(D2:D4) -> 1071.0135 | E5: =SUM(E2:E4) -> 16.045542 | F5: =SUM(F2:F4) -> 55.618989 | G5: =SUM(G2:G4) -> 167.97499 | H5: =SUM(H2:H4) -> 3 | I5: =SUM(I2:I4) -> 0 | J5: =SUM(J2:J4) -> 0 | ... W5: =SUM(W2:W4) -> 0.53200772 | AA5: Fried Shrimp | AB5: All Purpose Flour | AC5: =('All Facts'!F10*4)/3 -> 40 | AD5: Fishermans Market Tail On Peeled & Deveined Cooked Shrimp | AE5: 680
B7: Ingredient | C7: Grams Selected
A8: Fried Shrimp | B8: Grade A Large Egg | C8: =MROUND(AC4/AE4*C10,AC4) -> 150 | D8: =INDEX('All Facts'!G:G,MATCH(Recipie!$B8,'All Facts'!$B:$B,0),1)/INDEX('All Facts'!$F:$F,MATCH(Recipie!$B8,'All Facts'!$B:$B,0),1)*$C8 -> 210 | E8: =INDEX('All Facts'!H:H,MATCH(Recipie!$B8,'All Facts'!$B:$B,0),1)/INDEX('All Facts'!$F:$F,MATCH(Recipie!$B8,'All Facts'!$B:$B,0),1)*$C8 -> 15 | F8: =INDEX('All Facts'!I:I,MATCH(Recipie!$B8,'All Facts'!$B:$B,0),1)/INDEX('All Facts'!$F:$F,MATCH(Recipie!$B8,'All Facts'!$B:$B,0),1)*$C8 -> 0 | G8: =INDEX('All Facts'!J:J,MATCH(Recipie!$B8,'All Facts'!$B:$B,0),1)/INDEX('All Facts'!$F:$F,MATCH(Recipie!$B8,'All Facts'!$B:$B,0),1)*$C8 -> 18 | H8: =INDEX('All Facts'!K:K,MATCH(Recipie!$B8,'All Facts'!$B:$B,0),1)/INDEX('All Facts'!$F:$F,MATCH(Recipie!$B8,'All Facts'!$B:$B,0),1)*$C8 -> 4.5 | I8: =INDEX('All Facts'!L:L,MATCH(Recipie!$B8,'All Facts'!$B:$B,0),1)/INDEX('All Facts'!$F:$F,MATCH(Recipie!$B8,'All Facts'!$B:$B,0),1)*$C8 -> 0 | J8: =INDEX('All Facts'!M:M,MATCH(Recipie!$B8,'All Facts'!$B:$B,0),1)/INDEX('All Facts'!$F:$F,MATCH(Recipie!$B8,'All Facts'!$B:$B,0),1)*$C8 -> 0 | K8: =INDEX('All Facts'!N:N,MATCH(Recipie!$B8,'All Facts'!$B:$B,0),1)/INDEX('All Facts'!$F:$F,MATCH(Recipie!$B8,'All Facts'!$B:$B,0),1)*$C8 -> 555 | L8: =INDEX('All Facts'!O:O,MATCH(Recipie!$B8,'All Facts'!$B:$B,0),1)/INDEX('All Facts'!$F:$F,MATCH(Recipie!$B8,'All Facts'!$B:$B,0),1)*$C8 -> 210 | M8: =INDEX('All Facts'!P:P,MATCH(Recipie!$B8,'All Facts'!$B:$B,0),1)/INDEX('All Facts'!$F:$F,MATCH(Recipie!$B8,'All Facts'!$B:$B,0),1)*$C8 -> 3 | N8: =INDEX('All Facts'!Q:Q,MATCH(Recipie!$B8,'All Facts'!$B:$B,0),1)/INDEX('All Facts'!$F:$F,MATCH(Recipie!$B8,'All Facts'!$B:$B,0),1)*$C8 -> 90 | O8: =INDEX('All Facts'!R:R,MATCH(Recipie!$B8,'All Facts'!$B:$B,0),1)/INDEX('All Facts'!$F:$F,MATCH(Recipie!$B8,'All Facts'!$B:$B,0),1)*$C8 -> 2.7 | P8: =INDEX('All Facts'!S:S,MATCH(Recipie!$B8,'All Facts'!$B:$B,0),1)/INDEX('All Facts'!$F:$F,MATCH(Recipie!$B8,'All Facts'!$B:$B,0),1)*$C8 -> 0 | Q8: =INDEX('All Facts'!T:T,MATCH(Recipie!$B8,'All Facts'!$B:$B,0),1)/INDEX('All Facts'!$F:$F,MATCH(Recipie!$B8,'All Facts'!$B:$B,0),1)*$C8 -> 0 | R8: =INDEX('All Facts'!U:U,MATCH(Recipie!$B8,'All Facts'!$B:$B,0),1)/INDEX('All Facts'!$F:$F,MATCH(Recipie!$B8,'All Facts'!$B:$B,0),1)*$C8 -> 0 | S8: =INDEX('All Facts'!V:V,MATCH(Recipie!$B8,'All Facts'!$B:$B,0),1)/INDEX('All Facts'!$F:$F,MATCH(Recipie!$B8,'All Facts'!$B:$B,0),1)*$C8 -> 0 | T8: =INDEX('All Facts'!W:W,MATCH(Recipie!$B8,'All Facts'!$B:$B,0),1)/INDEX('All Facts'!$F:$F,MATCH(Recipie!$B8,'All Facts'!$B:$B,0),1)*$C8 -> 0 | U8: =INDEX('All Facts'!X:X,MATCH(Recipie!$B8,'All Facts'!$B:$B,0),1)/INDEX('All Facts'!$F:$F,MATCH(Recipie!$B8,'All Facts'!$B:$B,0),1)*$C8 -> 0 | V8: =INDEX('All Facts'!Y:Y,MATCH(Recipie!$B8,'All Facts'!$B:$B,0),1)/INDEX('All Facts'!$F:$F,MATCH(Recipie!$B8,'All Facts'!$B:$B,0),1)*$C8 -> 0 | W8: =INDEX('All Facts'!Z:Z,MATCH(Recipie!$B8,'All Facts'!$B:$B,0),1)/INDEX('All Facts'!$F:$F,MATCH(Recipie!$B8,'All Facts'!$B:$B,0),1)*$C8 -> 0
A9: Fried Shrimp | B9: All Purpose Flour | C9: =AC5/AE5*C10 -> 66.176471 | D9: =INDEX('All Facts'!G:G,MATCH(Recipie!$B9,'All Facts'!$B:$B,0),1)/INDEX('All Facts'!$F:$F,MATCH(Recipie!$B9,'All Facts'!$B:$B,0),1)*$C9 -> 242.64706 | E9: =INDEX('All Facts'!H:H,MATCH(Recipie!$B9,'All Facts'!$B:$B,0),1)/INDEX('All Facts'!$F:$F,MATCH(Recipie!$B9,'All Facts'!$B:$B,0),1)*$C9 -> 0 | F9: =INDEX('All Facts'!I:I,MATCH(Recipie!$B9,'All Facts'!$B:$B,0),1)/INDEX('All Facts'!$F:$F,MATCH(Recipie!$B9,'All Facts'!$B:$B,0),1)*$C9 -> 50.735294 | G9: =INDEX('All Facts'!J:J,MATCH(Recipie!$B9,'All Facts'!$B:$B,0),1)/INDEX('All Facts'!$F:$F,MATCH(Recipie!$B9,'All Facts'!$B:$B,0),1)*$C9 -> 4.4117647 | H9: =INDEX('All Facts'!K:K,MATCH(Recipie!$B9,'All Facts'!$B:$B,0),1)/INDEX('All Facts'!$F:$F,MATCH(Recipie!$B9,'All Facts'!$B:$B,0),1)*$C9 -> 0 | I9: =INDEX('All Facts'!L:L,MATCH(Recipie!$B9,'All Facts'!$B:$B,0),1)/INDEX('All Facts'!$F:$F,MATCH(Recipie!$B9,'All Facts'!$B:$B,0),1)*$C9 -> 0 | J9: =INDEX('All Facts'!M:M,MATCH(Recipie!$B9,'All Facts'!$B:$B,0),1)/INDEX('All Facts'!$F:$F,MATCH(Recipie!$B9,'All Facts'!$B:$B,0),1)*$C9 -> 0 | K9: =INDEX('All Facts'!N:N,MATCH(Recipie!$B9,'All Facts'!$B:$B,0),1)/INDEX('All Facts'!$F:$F,MATCH(Recipie!$B9,'All Facts'!$B:$B,0),1)*$C9 -> 0 | L9: =INDEX('All Facts'!O:O,MATCH(Recipie!$B9,'All Facts'!$B:$B,0),1)/INDEX('All Facts'!$F:$F,MATCH(Recipie!$B9,'All Facts'!$B:$B,0),1)*$C9 -> 0 | M9: =INDEX('All Facts'!P:P,MATCH(Recipie!$B9,'All Facts'!$B:$B,0),1)/INDEX('All Facts'!$F:$F,MATCH(Recipie!$B9,'All Facts'!$B:$B,0),1)*$C9 -> 0 | N9: =INDEX('All Facts'!Q:Q,MATCH(Recipie!$B9,'All Facts'!$B:$B,0),1)/INDEX('All Facts'!$F:$F,MATCH(Recipie!$B9,'All Facts'!$B:$B,0),1)*$C9 -> 0 | O9: =INDEX('All Facts'!R:R,MATCH(Recipie!$B9,'All Facts'!$B:$B,0),1)/INDEX('All Facts'!$F:$F,MATCH(Recipie!$B9,'All Facts'!$B:$B,0),1)*$C9 -> 2.8676471 | P9: =INDEX('All Facts'!S:S,MATCH(Recipie!$B9,'All Facts'!$B:$B,0),1)/INDEX('All Facts'!$F:$F,MATCH(Recipie!$B9,'All Facts'!$B:$B,0),1)*$C9 -> 66.176471 | Q9: =INDEX('All Facts'!T:T,MATCH(Recipie!$B9,'All Facts'!$B:$B,0),1)/INDEX('All Facts'!$F:$F,MATCH(Recipie!$B9,'All Facts'!$B:$B,0),1)*$C9 -> 0 | R9: =INDEX('All Facts'!U:U,MATCH(Recipie!$B9,'All Facts'!$B:$B,0),1)/INDEX('All Facts'!$F:$F,MATCH(Recipie!$B9,'All Facts'!$B:$B,0),1)*$C9 -> 0 | S9: =INDEX('All Facts'!V:V,MATCH(Recipie!$B9,'All Facts'!$B:$B,0),1)/INDEX('All Facts'!$F:$F,MATCH(Recipie!$B9,'All Facts'!$B:$B,0),1)*$C9 -> 0 | T9: =INDEX('All Facts'!W:W,MATCH(Recipie!$B9,'All Facts'!$B:$B,0),1)/INDEX('All Facts'!$F:$F,MATCH(Recipie!$B9,'All Facts'!$B:$B,0),1)*$C9 -> 0 | U9: =INDEX('All Facts'!X:X,MATCH(Recipie!$B9,'All Facts'!$B:$B,0),1)/INDEX('All Facts'!$F:$F,MATCH(Recipie!$B9,'All Facts'!$B:$B,0),1)*$C9 -> 110.29412 | V9: =INDEX('All Facts'!Y:Y,MATCH(Recipie!$B9,'All Facts'!$B:$B,0),1)/INDEX('All Facts'!$F:$F,MATCH(Recipie!$B9,'All Facts'!$B:$B,0),1)*$C9 -> 3.0882353 | W9: =INDEX('All Facts'!Z:Z,MATCH(Recipie!$B9,'All Facts'!$B:$B,0),1)/INDEX('All Facts'!$F:$F,MATCH(Recipie!$B9,'All Facts'!$B:$B,0),1)*$C9 -> 0.48529412
A10: Fried Shrimp | B10: Fishermans Market Tail On Peeled & Deveined Cooked Shrimp | C10: =Solver!C9 -> 1125 | D10: =INDEX('All Facts'!G:G,MATCH(Recipie!$B10,'All Facts'!$B:$B,0),1)/INDEX('All Facts'!$F:$F,MATCH(Recipie!$B10,'All Facts'!$B:$B,0),1)*$C10 -> 595.58824 | E10: =INDEX('All Facts'!H:H,MATCH(Recipie!$B10,'All Facts'!$B:$B,0),1)/INDEX('All Facts'!$F:$F,MATCH(Recipie!$B10,'All Facts'!$B:$B,0),1)*$C10 -> 0 | F10: =INDEX('All Facts'!I:I,MATCH(Recipie!$B10,'All Facts'!$B:$B,0),1)/INDEX('All Facts'!$F:$F,MATCH(Recipie!$B10,'All Facts'!$B:$B,0),1)*$C10 -> 0 | G10: =INDEX('All Facts'!J:J,MATCH(Recipie!$B10,'All Facts'!$B:$B,0),1)/INDEX('All Facts'!$F:$F,MATCH(Recipie!$B10,'All Facts'!$B:$B,0),1)*$C10 -> 145.58824 | H10: =INDEX('All Facts'!K:K,MATCH(Recipie!$B10,'All Facts'!$B:$B,0),1)/INDEX('All Facts'!$F:$F,MATCH(Recipie!$B10,'All Facts'!$B:$B,0),1)*$C10 -> 0 | I10: =INDEX('All Facts'!L:L,MATCH(Recipie!$B10,'All Facts'!$B:$B,0),1)/INDEX('All Facts'!$F:$F,MATCH(Recipie!$B10,'All Facts'!$B:$B,0),1)*$C10 -> 0 | J10: =INDEX('All Facts'!M:M,MATCH(Recipie!$B10,'All Facts'!$B:$B,0),1)/INDEX('All Facts'!$F:$F,MATCH(Recipie!$B10,'All Facts'!$B:$B,0),1)*$C10 -> 0 | K10: =INDEX('All Facts'!N:N,MATCH(Recipie!$B10,'All Facts'!$B:$B,0),1)/INDEX('All Facts'!$F:$F,MATCH(Recipie!$B10,'All Facts'!$B:$B,0),1)*$C10 -> 1588.2353 | L10: =INDEX('All Facts'!O:O,MATCH(Recipie!$B10,'All Facts'!$B:$B,0),1)/INDEX('All Facts'!$F:$F,MATCH(Recipie!$B10,'All Facts'!$B:$B,0),1)*$C10 -> 5294.1176 | M10: =INDEX('All Facts'!P:P,MATCH(Recipie!$B10,'All Facts'!$B:$B,0),1)/INDEX('All Facts'!$F:$F,MATCH(Recipie!$B10,'All Facts'!$B:$B,0),1)*$C10 -> 0 | N10: =INDEX('All Facts'!Q:Q,MATCH(Recipie!$B10,'All Facts'!$B:$B,0),1)/INDEX('All Facts'!$F:$F,MATCH(Recipie!$B10,'All Facts'!$B:$B,0),1)*$C10 -> 0 | O10: =INDEX('All Facts'!R:R,MATCH(Recipie!$B10,'All Facts'!$B:$B,0),1)/INDEX('All Facts'!$F:$F,MATCH(Recipie!$B10,'All Facts'!$B:$B,0),1)*$C10 -> 0 | P10: =INDEX('All Facts'!S:S,MATCH(Recipie!$B10,'All Facts'!$B:$B,0),1)/INDEX('All Facts'!$F:$F,MATCH(Recipie!$B10,'All Facts'!$B:$B,0),1)*$C10 -> 0 | Q10: =INDEX('All Facts'!T:T,MATCH(Recipie!$B10,'All Facts'!$B:$B,0),1)/INDEX('All Facts'!$F:$F,MATCH(Recipie!$B10,'All Facts'!$B:$B,0),1)*$C10 -> 0 | R10: =INDEX('All Facts'!U:U,MATCH(Recipie!$B10,'All Facts'!$B:$B,0),1)/INDEX('All Facts'!$F:$F,MATCH(Recipie!$B10,'All Facts'!$B:$B,0),1)*$C10 -> 0 | S10: =INDEX('All Facts'!V:V,MATCH(Recipie!$B10,'All Facts'!$B:$B,0),1)/INDEX('All Facts'!$F:$F,MATCH(Recipie!$B10,'All Facts'!$B:$B,0),1)*$C10 -> 0 | T10: =INDEX('All Facts'!W:W,MATCH(Recipie!$B10,'All Facts'!$B:$B,0),1)/INDEX('All Facts'!$F:$F,MATCH(Recipie!$B10,'All Facts'!$B:$B,0),1)*$C10 -> 0 | U10: =INDEX('All Facts'!X:X,MATCH(Recipie!$B10,'All Facts'!$B:$B,0),1)/INDEX('All Facts'!$F:$F,MATCH(Recipie!$B10,'All Facts'!$B:$B,0),1)*$C10 -> 0 | V10: =INDEX('All Facts'!Y:Y,MATCH(Recipie!$B10,'All Facts'!$B:$B,0),1)/INDEX('All Facts'!$F:$F,MATCH(Recipie!$B10,'All Facts'!$B:$B,0),1)*$C10 -> 0 | W10: =INDEX('All Facts'!Z:Z,MATCH(Recipie!$B10,'All Facts'!$B:$B,0),1)/INDEX('All Facts'!$F:$F,MATCH(Recipie!$B10,'All Facts'!$B:$B,0),1)*$C10 -> 0
A11: Fried Shrimp | B11: Total | C11: =SUM(C8:C10) -> 1341.1765 | D11: =SUM(D8:D10) -> 1048.2353 | E11: =SUM(E8:E10) -> 15 | F11: =SUM(F8:F10) -> 50.735294 | G11: =SUM(G8:G10) -> 168 | H11: =SUM(H8:H10) -> 4.5 | I11: =SUM(I8:I10) -> 0 | J11: =SUM(J8:J10) -> 0 | ... W11: =SUM(W8:W10) -> 0.48529412
B13: Ingredient | C13: Grams Selected
A14: Fried Shrimp 2 | B14: Grade A Large Egg | C14: =MROUND(AC4/AE4*C16,AC4) -> 150 | D14: =INDEX('All Facts'!G:G,MATCH(Recipie!$B14,'All Facts'!$B:$B,0),1)/INDEX('All Facts'!$F:$F,MATCH(Recipie!$B14,'All Facts'!$B:$B,0),1)*$C14 -> 210 | E14: =INDEX('All Facts'!H:H,MATCH(Recipie!$B14,'All Facts'!$B:$B,0),1)/INDEX('All Facts'!$F:$F,MATCH(Recipie!$B14,'All Facts'!$B:$B,0),1)*$C14 -> 15 | F14: =INDEX('All Facts'!I:I,MATCH(Recipie!$B14,'All Facts'!$B:$B,0),1)/INDEX('All Facts'!$F:$F,MATCH(Recipie!$B14,'All Facts'!$B:$B,0),1)*$C14 -> 0 | G14: =INDEX('All Facts'!J:J,MATCH(Recipie!$B14,'All Facts'!$B:$B,0),1)/INDEX('All Facts'!$F:$F,MATCH(Recipie!$B14,'All Facts'!$B:$B,0),1)*$C14 -> 18 | H14: =INDEX('All Facts'!K:K,MATCH(Recipie!$B14,'All Facts'!$B:$B,0),1)/INDEX('All Facts'!$F:$F,MATCH(Recipie!$B14,'All Facts'!$B:$B,0),1)*$C14 -> 4.5 | I14: =INDEX('All Facts'!L:L,MATCH(Recipie!$B14,'All Facts'!$B:$B,0),1)/INDEX('All Facts'!$F:$F,MATCH(Recipie!$B14,'All Facts'!$B:$B,0),1)*$C14 -> 0 | J14: =INDEX('All Facts'!M:M,MATCH(Recipie!$B14,'All Facts'!$B:$B,0),1)/INDEX('All Facts'!$F:$F,MATCH(Recipie!$B14,'All Facts'!$B:$B,0),1)*$C14 -> 0 | K14: =INDEX('All Facts'!N:N,MATCH(Recipie!$B14,'All Facts'!$B:$B,0),1)/INDEX('All Facts'!$F:$F,MATCH(Recipie!$B14,'All Facts'!$B:$B,0),1)*$C14 -> 555 | L14: =INDEX('All Facts'!O:O,MATCH(Recipie!$B14,'All Facts'!$B:$B,0),1)/INDEX('All Facts'!$F:$F,MATCH(Recipie!$B14,'All Facts'!$B:$B,0),1)*$C14 -> 210 | M14: =INDEX('All Facts'!P:P,MATCH(Recipie!$B14,'All Facts'!$B:$B,0),1)/INDEX('All Facts'!$F:$F,MATCH(Recipie!$B14,'All Facts'!$B:$B,0),1)*$C14 -> 3 | N14: =INDEX('All Facts'!Q:Q,MATCH(Recipie!$B14,'All Facts'!$B:$B,0),1)/INDEX('All Facts'!$F:$F,MATCH(Recipie!$B14,'All Facts'!$B:$B,0),1)*$C14 -> 90 | O14: =INDEX('All Facts'!R:R,MATCH(Recipie!$B14,'All Facts'!$B:$B,0),1)/INDEX('All Facts'!$F:$F,MATCH(Recipie!$B14,'All Facts'!$B:$B,0),1)*$C14 -> 2.7 | P14: =INDEX('All Facts'!S:S,MATCH(Recipie!$B14,'All Facts'!$B:$B,0),1)/INDEX('All Facts'!$F:$F,MATCH(Recipie!$B14,'All Facts'!$B:$B,0),1)*$C14 -> 0 | Q14: =INDEX('All Facts'!T:T,MATCH(Recipie!$B14,'All Facts'!$B:$B,0),1)/INDEX('All Facts'!$F:$F,MATCH(Recipie!$B14,'All Facts'!$B:$B,0),1)*$C14 -> 0 | R14: =INDEX('All Facts'!U:U,MATCH(Recipie!$B14,'All Facts'!$B:$B,0),1)/INDEX('All Facts'!$F:$F,MATCH(Recipie!$B14,'All Facts'!$B:$B,0),1)*$C14 -> 0 | S14: =INDEX('All Facts'!V:V,MATCH(Recipie!$B14,'All Facts'!$B:$B,0),1)/INDEX('All Facts'!$F:$F,MATCH(Recipie!$B14,'All Facts'!$B:$B,0),1)*$C14 -> 0 | T14: =INDEX('All Facts'!W:W,MATCH(Recipie!$B14,'All Facts'!$B:$B,0),1)/INDEX('All Facts'!$F:$F,MATCH(Recipie!$B14,'All Facts'!$B:$B,0),1)*$C14 -> 0 | U14: =INDEX('All Facts'!X:X,MATCH(Recipie!$B14,'All Facts'!$B:$B,0),1)/INDEX('All Facts'!$F:$F,MATCH(Recipie!$B14,'All Facts'!$B:$B,0),1)*$C14 -> 0 | V14: =INDEX('All Facts'!Y:Y,MATCH(Recipie!$B14,'All Facts'!$B:$B,0),1)/INDEX('All Facts'!$F:$F,MATCH(Recipie!$B14,'All Facts'!$B:$B,0),1)*$C14 -> 0 | W14: =INDEX('All Facts'!Z:Z,MATCH(Recipie!$B14,'All Facts'!$B:$B,0),1)/INDEX('All Facts'!$F:$F,MATCH(Recipie!$B14,'All Facts'!$B:$B,0),1)*$C14 -> 0
A15: Fried Shrimp 2 | B15: All Purpose Flour | C15: =AC5/AE5*C16 -> 66.176471 | D15: =INDEX('All Facts'!G:G,MATCH(Recipie!$B15,'All Facts'!$B:$B,0),1)/INDEX('All Facts'!$F:$F,MATCH(Recipie!$B15,'All Facts'!$B:$B,0),1)*$C15 -> 242.64706 | E15: =INDEX('All Facts'!H:H,MATCH(Recipie!$B15,'All Facts'!$B:$B,0),1)/INDEX('All Facts'!$F:$F,MATCH(Recipie!$B15,'All Facts'!$B:$B,0),1)*$C15 -> 0 | F15: =INDEX('All Facts'!I:I,MATCH(Recipie!$B15,'All Facts'!$B:$B,0),1)/INDEX('All Facts'!$F:$F,MATCH(Recipie!$B15,'All Facts'!$B:$B,0),1)*$C15 -> 50.735294 | G15: =INDEX('All Facts'!J:J,MATCH(Recipie!$B15,'All Facts'!$B:$B,0),1)/INDEX('All Facts'!$F:$F,MATCH(Recipie!$B15,'All Facts'!$B:$B,0),1)*$C15 -> 4.4117647 | H15: =INDEX('All Facts'!K:K,MATCH(Recipie!$B15,'All Facts'!$B:$B,0),1)/INDEX('All Facts'!$F:$F,MATCH(Recipie!$B15,'All Facts'!$B:$B,0),1)*$C15 -> 0 | I15: =INDEX('All Facts'!L:L,MATCH(Recipie!$B15,'All Facts'!$B:$B,0),1)/INDEX('All Facts'!$F:$F,MATCH(Recipie!$B15,'All Facts'!$B:$B,0),1)*$C15 -> 0 | J15: =INDEX('All Facts'!M:M,MATCH(Recipie!$B15,'All Facts'!$B:$B,0),1)/INDEX('All Facts'!$F:$F,MATCH(Recipie!$B15,'All Facts'!$B:$B,0),1)*$C15 -> 0 | K15: =INDEX('All Facts'!N:N,MATCH(Recipie!$B15,'All Facts'!$B:$B,0),1)/INDEX('All Facts'!$F:$F,MATCH(Recipie!$B15,'All Facts'!$B:$B,0),1)*$C15 -> 0 | L15: =INDEX('All Facts'!O:O,MATCH(Recipie!$B15,'All Facts'!$B:$B,0),1)/INDEX('All Facts'!$F:$F,MATCH(Recipie!$B15,'All Facts'!$B:$B,0),1)*$C15 -> 0 | M15: =INDEX('All Facts'!P:P,MATCH(Recipie!$B15,'All Facts'!$B:$B,0),1)/INDEX('All Facts'!$F:$F,MATCH(Recipie!$B15,'All Facts'!$B:$B,0),1)*$C15 -> 0 | N15: =INDEX('All Facts'!Q:Q,MATCH(Recipie!$B15,'All Facts'!$B:$B,0),1)/INDEX('All Facts'!$F:$F,MATCH(Recipie!$B15,'All Facts'!$B:$B,0),1)*$C15 -> 0 | O15: =INDEX('All Facts'!R:R,MATCH(Recipie!$B15,'All Facts'!$B:$B,0),1)/INDEX('All Facts'!$F:$F,MATCH(Recipie!$B15,'All Facts'!$B:$B,0),1)*$C15 -> 2.8676471 | P15: =INDEX('All Facts'!S:S,MATCH(Recipie!$B15,'All Facts'!$B:$B,0),1)/INDEX('All Facts'!$F:$F,MATCH(Recipie!$B15,'All Facts'!$B:$B,0),1)*$C15 -> 66.176471 | Q15: =INDEX('All Facts'!T:T,MATCH(Recipie!$B15,'All Facts'!$B:$B,0),1)/INDEX('All Facts'!$F:$F,MATCH(Recipie!$B15,'All Facts'!$B:$B,0),1)*$C15 -> 0 | R15: =INDEX('All Facts'!U:U,MATCH(Recipie!$B15,'All Facts'!$B:$B,0),1)/INDEX('All Facts'!$F:$F,MATCH(Recipie!$B15,'All Facts'!$B:$B,0),1)*$C15 -> 0 | S15: =INDEX('All Facts'!V:V,MATCH(Recipie!$B15,'All Facts'!$B:$B,0),1)/INDEX('All Facts'!$F:$F,MATCH(Recipie!$B15,'All Facts'!$B:$B,0),1)*$C15 -> 0 | T15: =INDEX('All Facts'!W:W,MATCH(Recipie!$B15,'All Facts'!$B:$B,0),1)/INDEX('All Facts'!$F:$F,MATCH(Recipie!$B15,'All Facts'!$B:$B,0),1)*$C15 -> 0 | U15: =INDEX('All Facts'!X:X,MATCH(Recipie!$B15,'All Facts'!$B:$B,0),1)/INDEX('All Facts'!$F:$F,MATCH(Recipie!$B15,'All Facts'!$B:$B,0),1)*$C15 -> 110.29412 | V15: =INDEX('All Facts'!Y:Y,MATCH(Recipie!$B15,'All Facts'!$B:$B,0),1)/INDEX('All Facts'!$F:$F,MATCH(Recipie!$B15,'All Facts'!$B:$B,0),1)*$C15 -> 3.0882353 | W15: =INDEX('All Facts'!Z:Z,MATCH(Recipie!$B15,'All Facts'!$B:$B,0),1)/INDEX('All Facts'!$F:$F,MATCH(Recipie!$B15,'All Facts'!$B:$B,0),1)*$C15 -> 0.48529412
A16: Fried Shrimp 2 | B16: Fishermans Market Tail On Peeled & Deveined Cooked Shrimp | C16: =Solver!C13 -> 1125 | D16: =INDEX('All Facts'!G:G,MATCH(Recipie!$B16,'All Facts'!$B:$B,0),1)/INDEX('All Facts'!$F:$F,MATCH(Recipie!$B16,'All Facts'!$B:$B,0),1)*$C16 -> 595.58824 | E16: =INDEX('All Facts'!H:H,MATCH(Recipie!$B16,'All Facts'!$B:$B,0),1)/INDEX('All Facts'!$F:$F,MATCH(Recipie!$B16,'All Facts'!$B:$B,0),1)*$C16 -> 0 | F16: =INDEX('All Facts'!I:I,MATCH(Recipie!$B16,'All Facts'!$B:$B,0),1)/INDEX('All Facts'!$F:$F,MATCH(Recipie!$B16,'All Facts'!$B:$B,0),1)*$C16 -> 0 | G16: =INDEX('All Facts'!J:J,MATCH(Recipie!$B16,'All Facts'!$B:$B,0),1)/INDEX('All Facts'!$F:$F,MATCH(Recipie!$B16,'All Facts'!$B:$B,0),1)*$C16 -> 145.58824 | H16: =INDEX('All Facts'!K:K,MATCH(Recipie!$B16,'All Facts'!$B:$B,0),1)/INDEX('All Facts'!$F:$F,MATCH(Recipie!$B16,'All Facts'!$B:$B,0),1)*$C16 -> 0 | I16: =INDEX('All Facts'!L:L,MATCH(Recipie!$B16,'All Facts'!$B:$B,0),1)/INDEX('All Facts'!$F:$F,MATCH(Recipie!$B16,'All Facts'!$B:$B,0),1)*$C16 -> 0 | J16: =INDEX('All Facts'!M:M,MATCH(Recipie!$B16,'All Facts'!$B:$B,0),1)/INDEX('All Facts'!$F:$F,MATCH(Recipie!$B16,'All Facts'!$B:$B,0),1)*$C16 -> 0 | K16: =INDEX('All Facts'!N:N,MATCH(Recipie!$B16,'All Facts'!$B:$B,0),1)/INDEX('All Facts'!$F:$F,MATCH(Recipie!$B16,'All Facts'!$B:$B,0),1)*$C16 -> 1588.2353 | L16: =INDEX('All Facts'!O:O,MATCH(Recipie!$B16,'All Facts'!$B:$B,0),1)/INDEX('All Facts'!$F:$F,MATCH(Recipie!$B16,'All Facts'!$B:$B,0),1)*$C16 -> 5294.1176 | M16: =INDEX('All Facts'!P:P,MATCH(Recipie!$B16,'All Facts'!$B:$B,0),1)/INDEX('All Facts'!$F:$F,MATCH(Recipie!$B16,'All Facts'!$B:$B,0),1)*$C16 -> 0 | N16: =INDEX('All Facts'!Q:Q,MATCH(Recipie!$B16,'All Facts'!$B:$B,0),1)/INDEX('All Facts'!$F:$F,MATCH(Recipie!$B16,'All Facts'!$B:$B,0),1)*$C16 -> 0 | O16: =INDEX('All Facts'!R:R,MATCH(Recipie!$B16,'All Facts'!$B:$B,0),1)/INDEX('All Facts'!$F:$F,MATCH(Recipie!$B16,'All Facts'!$B:$B,0),1)*$C16 -> 0 | P16: =INDEX('All Facts'!S:S,MATCH(Recipie!$B16,'All Facts'!$B:$B,0),1)/INDEX('All Facts'!$F:$F,MATCH(Recipie!$B16,'All Facts'!$B:$B,0),1)*$C16 -> 0 | Q16: =INDEX('All Facts'!T:T,MATCH(Recipie!$B16,'All Facts'!$B:$B,0),1)/INDEX('All Facts'!$F:$F,MATCH(Recipie!$B16,'All Facts'!$B:$B,0),1)*$C16 -> 0 | R16: =INDEX('All Facts'!U:U,MATCH(Recipie!$B16,'All Facts'!$B:$B,0),1)/INDEX('All Facts'!$F:$F,MATCH(Recipie!$B16,'All Facts'!$B:$B,0),1)*$C16 -> 0 | S16: =INDEX('All Facts'!V:V,MATCH(Recipie!$B16,'All Facts'!$B:$B,0),1)/INDEX('All Facts'!$F:$F,MATCH(Recipie!$B16,'All Facts'!$B:$B,0),1)*$C16 -> 0 | T16: =INDEX('All Facts'!W:W,MATCH(Recipie!$B16,'All Facts'!$B:$B,0),1)/INDEX('All Facts'!$F:$F,MATCH(Recipie!$B16,'All Facts'!$B:$B,0),1)*$C16 -> 0 | U16: =INDEX('All Facts'!X:X,MATCH(Recipie!$B16,'All Facts'!$B:$B,0),1)/INDEX('All Facts'!$F:$F,MATCH(Recipie!$B16,'All Facts'!$B:$B,0),1)*$C16 -> 0 | V16: =INDEX('All Facts'!Y:Y,MATCH(Recipie!$B16,'All Facts'!$B:$B,0),1)/INDEX('All Facts'!$F:$F,MATCH(Recipie!$B16,'All Facts'!$B:$B,0),1)*$C16 -> 0 | W16: =INDEX('All Facts'!Z:Z,MATCH(Recipie!$B16,'All Facts'!$B:$B,0),1)/INDEX('All Facts'!$F:$F,MATCH(Recipie!$B16,'All Facts'!$B:$B,0),1)*$C16 -> 0
A17: Fried Shrimp 2 | B17: Total | C17: =SUM(C14:C16) -> 1341.1765 | D17: =SUM(D14:D16) -> 1048.2353 | E17: =SUM(E14:E16) -> 15 | F17: =SUM(F14:F16) -> 50.735294 | G17: =SUM(G14:G16) -> 168 | H17: =SUM(H14:H16) -> 4.5 | I17: =SUM(I14:I16) -> 0 | J17: =SUM(J14:J16) -> 0 | ... W17: =SUM(W14:W16) -> 0.48529412
A19: Name | B19: Ingredient | C19: Grams Selected | D19: ='All Facts'!G19 -> 0 | E19: ='All Facts'!H19 -> 0 | F19: ='All Facts'!I19 -> 0 | G19: ='All Facts'!J19 -> 0 | H19: ='All Facts'!K19 -> 0 | I19: ='All Facts'!L19 -> 0 | J19: ='All Facts'!M19 -> 0 | K19: ='All Facts'!N19 -> 0 | ... W19: ='All Facts'!Z19 -> 0
A20: Chicken Nuggets 2 | B20: Grade A Large Egg | C20: =MROUND(AC2/AE2*C22,AC2) -> 100 | D20: =INDEX('All Facts'!G:G,MATCH(Recipie!$B20,'All Facts'!$B:$B,0),1)/INDEX('All Facts'!$F:$F,MATCH(Recipie!$B20,'All Facts'!$B:$B,0),1)*$C20 -> 140 | E20: =INDEX('All Facts'!H:H,MATCH(Recipie!$B20,'All Facts'!$B:$B,0),1)/INDEX('All Facts'!$F:$F,MATCH(Recipie!$B20,'All Facts'!$B:$B,0),1)*$C20 -> 10 | F20: =INDEX('All Facts'!I:I,MATCH(Recipie!$B20,'All Facts'!$B:$B,0),1)/INDEX('All Facts'!$F:$F,MATCH(Recipie!$B20,'All Facts'!$B:$B,0),1)*$C20 -> 0 | G20: =INDEX('All Facts'!J:J,MATCH(Recipie!$B20,'All Facts'!$B:$B,0),1)/INDEX('All Facts'!$F:$F,MATCH(Recipie!$B20,'All Facts'!$B:$B,0),1)*$C20 -> 12 | H20: =INDEX('All Facts'!K:K,MATCH(Recipie!$B20,'All Facts'!$B:$B,0),1)/INDEX('All Facts'!$F:$F,MATCH(Recipie!$B20,'All Facts'!$B:$B,0),1)*$C20 -> 3 | I20: =INDEX('All Facts'!L:L,MATCH(Recipie!$B20,'All Facts'!$B:$B,0),1)/INDEX('All Facts'!$F:$F,MATCH(Recipie!$B20,'All Facts'!$B:$B,0),1)*$C20 -> 0 | J20: =INDEX('All Facts'!M:M,MATCH(Recipie!$B20,'All Facts'!$B:$B,0),1)/INDEX('All Facts'!$F:$F,MATCH(Recipie!$B20,'All Facts'!$B:$B,0),1)*$C20 -> 0 | K20: =INDEX('All Facts'!N:N,MATCH(Recipie!$B20,'All Facts'!$B:$B,0),1)/INDEX('All Facts'!$F:$F,MATCH(Recipie!$B20,'All Facts'!$B:$B,0),1)*$C20 -> 370 | L20: =INDEX('All Facts'!O:O,MATCH(Recipie!$B20,'All Facts'!$B:$B,0),1)/INDEX('All Facts'!$F:$F,MATCH(Recipie!$B20,'All Facts'!$B:$B,0),1)*$C20 -> 140 | M20: =INDEX('All Facts'!P:P,MATCH(Recipie!$B20,'All Facts'!$B:$B,0),1)/INDEX('All Facts'!$F:$F,MATCH(Recipie!$B20,'All Facts'!$B:$B,0),1)*$C20 -> 2 | N20: =INDEX('All Facts'!Q:Q,MATCH(Recipie!$B20,'All Facts'!$B:$B,0),1)/INDEX('All Facts'!$F:$F,MATCH(Recipie!$B20,'All Facts'!$B:$B,0),1)*$C20 -> 60 | O20: =INDEX('All Facts'!R:R,MATCH(Recipie!$B20,'All Facts'!$B:$B,0),1)/INDEX('All Facts'!$F:$F,MATCH(Recipie!$B20,'All Facts'!$B:$B,0),1)*$C20 -> 1.8 | P20: =INDEX('All Facts'!S:S,MATCH(Recipie!$B20,'All Facts'!$B:$B,0),1)/INDEX('All Facts'!$F:$F,MATCH(Recipie!$B20,'All Facts'!$B:$B,0),1)*$C20 -> 0 | Q20: =INDEX('All Facts'!T:T,MATCH(Recipie!$B20,'All Facts'!$B:$B,0),1)/INDEX('All Facts'!$F:$F,MATCH(Recipie!$B20,'All Facts'!$B:$B,0),1)*$C20 -> 0 | R20: =INDEX('All Facts'!U:U,MATCH(Recipie!$B20,'All Facts'!$B:$B,0),1)/INDEX('All Facts'!$F:$F,MATCH(Recipie!$B20,'All Facts'!$B:$B,0),1)*$C20 -> 0 | S20: =INDEX('All Facts'!V:V,MATCH(Recipie!$B20,'All Facts'!$B:$B,0),1)/INDEX('All Facts'!$F:$F,MATCH(Recipie!$B20,'All Facts'!$B:$B,0),1)*$C20 -> 0 | T20: =INDEX('All Facts'!W:W,MATCH(Recipie!$B20,'All Facts'!$B:$B,0),1)/INDEX('All Facts'!$F:$F,MATCH(Recipie!$B20,'All Facts'!$B:$B,0),1)*$C20 -> 0 | U20: =INDEX('All Facts'!X:X,MATCH(Recipie!$B20,'All Facts'!$B:$B,0),1)/INDEX('All Facts'!$F:$F,MATCH(Recipie!$B20,'All Facts'!$B:$B,0),1)*$C20 -> 0 | V20: =INDEX('All Facts'!Y:Y,MATCH(Recipie!$B20,'All Facts'!$B:$B,0),1)/INDEX('All Facts'!$F:$F,MATCH(Recipie!$B20,'All Facts'!$B:$B,0),1)*$C20 -> 0 | W20: =INDEX('All Facts'!Z:Z,MATCH(Recipie!$B20,'All Facts'!$B:$B,0),1)/INDEX('All Facts'!$F:$F,MATCH(Recipie!$B20,'All Facts'!$B:$B,0),1)*$C20 -> 0
A21: Chicken Nuggets 2 | B21: All Purpose Flour | C21: =AC3/AE3*C22 -> 72.546508 | D21: =INDEX('All Facts'!G:G,MATCH(Recipie!$B21,'All Facts'!$B:$B,0),1)/INDEX('All Facts'!$F:$F,MATCH(Recipie!$B21,'All Facts'!$B:$B,0),1)*$C21 -> 266.00386 | E21: =INDEX('All Facts'!H:H,MATCH(Recipie!$B21,'All Facts'!$B:$B,0),1)/INDEX('All Facts'!$F:$F,MATCH(Recipie!$B21,'All Facts'!$B:$B,0),1)*$C21 -> 0 | F21: =INDEX('All Facts'!I:I,MATCH(Recipie!$B21,'All Facts'!$B:$B,0),1)/INDEX('All Facts'!$F:$F,MATCH(Recipie!$B21,'All Facts'!$B:$B,0),1)*$C21 -> 55.618989 | G21: =INDEX('All Facts'!J:J,MATCH(Recipie!$B21,'All Facts'!$B:$B,0),1)/INDEX('All Facts'!$F:$F,MATCH(Recipie!$B21,'All Facts'!$B:$B,0),1)*$C21 -> 4.8364338 | H21: =INDEX('All Facts'!K:K,MATCH(Recipie!$B21,'All Facts'!$B:$B,0),1)/INDEX('All Facts'!$F:$F,MATCH(Recipie!$B21,'All Facts'!$B:$B,0),1)*$C21 -> 0 | I21: =INDEX('All Facts'!L:L,MATCH(Recipie!$B21,'All Facts'!$B:$B,0),1)/INDEX('All Facts'!$F:$F,MATCH(Recipie!$B21,'All Facts'!$B:$B,0),1)*$C21 -> 0 | J21: =INDEX('All Facts'!M:M,MATCH(Recipie!$B21,'All Facts'!$B:$B,0),1)/INDEX('All Facts'!$F:$F,MATCH(Recipie!$B21,'All Facts'!$B:$B,0),1)*$C21 -> 0 | K21: =INDEX('All Facts'!N:N,MATCH(Recipie!$B21,'All Facts'!$B:$B,0),1)/INDEX('All Facts'!$F:$F,MATCH(Recipie!$B21,'All Facts'!$B:$B,0),1)*$C21 -> 0 | L21: =INDEX('All Facts'!O:O,MATCH(Recipie!$B21,'All Facts'!$B:$B,0),1)/INDEX('All Facts'!$F:$F,MATCH(Recipie!$B21,'All Facts'!$B:$B,0),1)*$C21 -> 0 | M21: =INDEX('All Facts'!P:P,MATCH(Recipie!$B21,'All Facts'!$B:$B,0),1)/INDEX('All Facts'!$F:$F,MATCH(Recipie!$B21,'All Facts'!$B:$B,0),1)*$C21 -> 0 | N21: =INDEX('All Facts'!Q:Q,MATCH(Recipie!$B21,'All Facts'!$B:$B,0),1)/INDEX('All Facts'!$F:$F,MATCH(Recipie!$B21,'All Facts'!$B:$B,0),1)*$C21 -> 0 | O21: =INDEX('All Facts'!R:R,MATCH(Recipie!$B21,'All Facts'!$B:$B,0),1)/INDEX('All Facts'!$F:$F,MATCH(Recipie!$B21,'All Facts'!$B:$B,0),1)*$C21 -> 3.143682 | P21: =INDEX('All Facts'!S:S,MATCH(Recipie!$B21,'All Facts'!$B:$B,0),1)/INDEX('All Facts'!$F:$F,MATCH(Recipie!$B21,'All Facts'!$B:$B,0),1)*$C21 -> 72.546508 | Q21: =INDEX('All Facts'!T:T,MATCH(Recipie!$B21,'All Facts'!$B:$B,0),1)/INDEX('All Facts'!$F:$F,MATCH(Recipie!$B21,'All Facts'!$B:$B,0),1)*$C21 -> 0 | R21: =INDEX('All Facts'!U:U,MATCH(Recipie!$B21,'All Facts'!$B:$B,0),1)/INDEX('All Facts'!$F:$F,MATCH(Recipie!$B21,'All Facts'!$B:$B,0),1)*$C21 -> 0 | S21: =INDEX('All Facts'!V:V,MATCH(Recipie!$B21,'All Facts'!$B:$B,0),1)/INDEX('All Facts'!$F:$F,MATCH(Recipie!$B21,'All Facts'!$B:$B,0),1)*$C21 -> 0 | T21: =INDEX('All Facts'!W:W,MATCH(Recipie!$B21,'All Facts'!$B:$B,0),1)/INDEX('All Facts'!$F:$F,MATCH(Recipie!$B21,'All Facts'!$B:$B,0),1)*$C21 -> 0 | U21: =INDEX('All Facts'!X:X,MATCH(Recipie!$B21,'All Facts'!$B:$B,0),1)/INDEX('All Facts'!$F:$F,MATCH(Recipie!$B21,'All Facts'!$B:$B,0),1)*$C21 -> 120.91085 | V21: =INDEX('All Facts'!Y:Y,MATCH(Recipie!$B21,'All Facts'!$B:$B,0),1)/INDEX('All Facts'!$F:$F,MATCH(Recipie!$B21,'All Facts'!$B:$B,0),1)*$C21 -> 3.3855037 | W21: =INDEX('All Facts'!Z:Z,MATCH(Recipie!$B21,'All Facts'!$B:$B,0),1)/INDEX('All Facts'!$F:$F,MATCH(Recipie!$B21,'All Facts'!$B:$B,0),1)*$C21 -> 0.53200772
A22: Chicken Nuggets 2 | B22: Chicken Breast | C22: =Solver!C15 -> 677.10074 | D22: =INDEX('All Facts'!G:G,MATCH(Recipie!$B22,'All Facts'!$B:$B,0),1)/INDEX('All Facts'!$F:$F,MATCH(Recipie!$B22,'All Facts'!$B:$B,0),1)*$C22 -> 665.00965 | E22: =INDEX('All Facts'!H:H,MATCH(Recipie!$B22,'All Facts'!$B:$B,0),1)/INDEX('All Facts'!$F:$F,MATCH(Recipie!$B22,'All Facts'!$B:$B,0),1)*$C22 -> 6.0455423 | F22: =INDEX('All Facts'!I:I,MATCH(Recipie!$B22,'All Facts'!$B:$B,0),1)/INDEX('All Facts'!$F:$F,MATCH(Recipie!$B22,'All Facts'!$B:$B,0),1)*$C22 -> 0 | G22: =INDEX('All Facts'!J:J,MATCH(Recipie!$B22,'All Facts'!$B:$B,0),1)/INDEX('All Facts'!$F:$F,MATCH(Recipie!$B22,'All Facts'!$B:$B,0),1)*$C22 -> 151.13856 | H22: =INDEX('All Facts'!K:K,MATCH(Recipie!$B22,'All Facts'!$B:$B,0),1)/INDEX('All Facts'!$F:$F,MATCH(Recipie!$B22,'All Facts'!$B:$B,0),1)*$C22 -> 0 | I22: =INDEX('All Facts'!L:L,MATCH(Recipie!$B22,'All Facts'!$B:$B,0),1)/INDEX('All Facts'!$F:$F,MATCH(Recipie!$B22,'All Facts'!$B:$B,0),1)*$C22 -> 0 | J22: =INDEX('All Facts'!M:M,MATCH(Recipie!$B22,'All Facts'!$B:$B,0),1)/INDEX('All Facts'!$F:$F,MATCH(Recipie!$B22,'All Facts'!$B:$B,0),1)*$C22 -> 0 | K22: =INDEX('All Facts'!N:N,MATCH(Recipie!$B22,'All Facts'!$B:$B,0),1)/INDEX('All Facts'!$F:$F,MATCH(Recipie!$B22,'All Facts'!$B:$B,0),1)*$C22 -> 483.64338 | L22: =INDEX('All Facts'!O:O,MATCH(Recipie!$B22,'All Facts'!$B:$B,0),1)/INDEX('All Facts'!$F:$F,MATCH(Recipie!$B22,'All Facts'!$B:$B,0),1)*$C22 -> 453.41567 | M22: =INDEX('All Facts'!P:P,MATCH(Recipie!$B22,'All Facts'!$B:$B,0),1)/INDEX('All Facts'!$F:$F,MATCH(Recipie!$B22,'All Facts'!$B:$B,0),1)*$C22 -> 0 | N22: =INDEX('All Facts'!Q:Q,MATCH(Recipie!$B22,'All Facts'!$B:$B,0),1)/INDEX('All Facts'!$F:$F,MATCH(Recipie!$B22,'All Facts'!$B:$B,0),1)*$C22 -> 0 | O22: =INDEX('All Facts'!R:R,MATCH(Recipie!$B22,'All Facts'!$B:$B,0),1)/INDEX('All Facts'!$F:$F,MATCH(Recipie!$B22,'All Facts'!$B:$B,0),1)*$C22 -> 2.1763952 | P22: =INDEX('All Facts'!S:S,MATCH(Recipie!$B22,'All Facts'!$B:$B,0),1)/INDEX('All Facts'!$F:$F,MATCH(Recipie!$B22,'All Facts'!$B:$B,0),1)*$C22 -> 0 | Q22: =INDEX('All Facts'!T:T,MATCH(Recipie!$B22,'All Facts'!$B:$B,0),1)/INDEX('All Facts'!$F:$F,MATCH(Recipie!$B22,'All Facts'!$B:$B,0),1)*$C22 -> 0 | R22: =INDEX('All Facts'!U:U,MATCH(Recipie!$B22,'All Facts'!$B:$B,0),1)/INDEX('All Facts'!$F:$F,MATCH(Recipie!$B22,'All Facts'!$B:$B,0),1)*$C22 -> 0 | S22: =INDEX('All Facts'!V:V,MATCH(Recipie!$B22,'All Facts'!$B:$B,0),1)/INDEX('All Facts'!$F:$F,MATCH(Recipie!$B22,'All Facts'!$B:$B,0),1)*$C22 -> 0 | T22: =INDEX('All Facts'!W:W,MATCH(Recipie!$B22,'All Facts'!$B:$B,0),1)/INDEX('All Facts'!$F:$F,MATCH(Recipie!$B22,'All Facts'!$B:$B,0),1)*$C22 -> 0 | U22: =INDEX('All Facts'!X:X,MATCH(Recipie!$B22,'All Facts'!$B:$B,0),1)/INDEX('All Facts'!$F:$F,MATCH(Recipie!$B22,'All Facts'!$B:$B,0),1)*$C22 -> 0 | V22: =INDEX('All Facts'!Y:Y,MATCH(Recipie!$B22,'All Facts'!$B:$B,0),1)/INDEX('All Facts'!$F:$F,MATCH(Recipie!$B22,'All Facts'!$B:$B,0),1)*$C22 -> 0 | W22: =INDEX('All Facts'!Z:Z,MATCH(Recipie!$B22,'All Facts'!$B:$B,0),1)/INDEX('All Facts'!$F:$F,MATCH(Recipie!$B22,'All Facts'!$B:$B,0),1)*$C22 -> 0
A23: Chicken Nuggets 2 | B23: Total | C23: =SUM(C20:C22) -> 849.64724 | D23: =SUM(D20:D22) -> 1071.0135 | E23: =SUM(E20:E22) -> 16.045542 | F23: =SUM(F20:F22) -> 55.618989 | G23: =SUM(G20:G22) -> 167.97499 | H23: =SUM(H20:H22) -> 3 | I23: =SUM(I20:I22) -> 0 | J23: =SUM(J20:J22) -> 0 | ... W23: =SUM(W20:W22) -> 0.53200772

Sheet Solver
A1: Everyday | B1: Name | C1: Grams | D1: Calories | E1: Total Fat Grams | F1: Total Carb Grams | G1: Protein Grams | H1: Saturated Fat Grams | I1: Polysaturated Fat Grams | J1: Monosaturated Fat Grams | K1: Cholesterol mg | L1: Sodium mg | M1: Vitamin D mcg | N1: Calcium mg | O1: Iron mg | P1: Potassium mg | Q1: Dietary Fiber grams | R1: Total Sugars Grams | S1: Vitamin C mg | T1: Vitamin B6 mg | U1: Folic Acid mcg | V1: Niacin mg | W1: Thiamin mg | Z1: ='All Facts'!B11 -> Colby Jack Cheese | AA1: Day | AB1: Grams | AC1: Calories | AD1: Total Fat Grams | AE1: Total Carb Grams | AF1: Protein Grams | AG1: Saturated Fat Grams | AH1: Polysaturated Fat Grams | AI1: Monosaturated Fat Grams | AJ1: Cholesterol mg | AK1: Sodium mg | AL1: Vitamin D mcg | AM1: Calcium mg | AN1: Iron mg | AO1: Potassium mg | AP1: Dietary Fiber grams | AQ1: Total Sugars Grams | AR1: Vitamin C mg | AS1: Vitamin B6 mg | AT1: Folic Acid mcg | AU1: Niacin mg | AV1: Thiamin mg | AW1: Cubes
B2: Pre-Washed Russet Potatoes | C2: 150 | D2: =INDEX('All Facts'!G:G,MATCH(Solver!$B2,'All Facts'!$B:$B,0),1)/INDEX('All Facts'!$F:$F,MATCH(Solver!$B2,'All Facts'!$B:$B,0),1)*$C2 -> 111.48649 | E2: =INDEX('All Facts'!H:H,MATCH(Solver!$B2,'All Facts'!$B:$B,0),1)/INDEX('All Facts'!$F:$F,MATCH(Solver!$B2,'All Facts'!$B:$B,0),1)*$C2 -> 0 | F2: =INDEX('All Facts'!I:I,MATCH(Solver!$B2,'All Facts'!$B:$B,0),1)/INDEX('All Facts'!$F:$F,MATCH(Solver!$B2,'All Facts'!$B:$B,0),1)*$C2 -> 26.351351 | G2: =INDEX('All Facts'!J:J,MATCH(Solver!$B2,'All Facts'!$B:$B,0),1)/INDEX('All Facts'!$F:$F,MATCH(Solver!$B2,'All Facts'!$B:$B,0),1)*$C2 -> 3.0405405 | H2: =INDEX('All Facts'!K:K,MATCH(Solver!$B2,'All Facts'!$B:$B,0),1)/INDEX('All Facts'!$F:$F,MATCH(Solver!$B2,'All Facts'!$B:$B,0),1)*$C2 -> 0 | I2: =INDEX('All Facts'!L:L,MATCH(Solver!$B2,'All Facts'!$B:$B,0),1)/INDEX('All Facts'!$F:$F,MATCH(Solver!$B2,'All Facts'!$B:$B,0),1)*$C2 -> 0 | J2: =INDEX('All Facts'!M:M,MATCH(Solver!$B2,'All Facts'!$B:$B,0),1)/INDEX('All Facts'!$F:$F,MATCH(Solver!$B2,'All Facts'!$B:$B,0),1)*$C2 -> 0 | K2: =INDEX('All Facts'!N:N,MATCH(Solver!$B2,'All Facts'!$B:$B,0),1)/INDEX('All Facts'!$F:$F,MATCH(Solver!$B2,'All Facts'!$B:$B,0),1)*$C2 -> 0 | L2: =INDEX('All Facts'!O:O,MATCH(Solver!$B2,'All Facts'!$B:$B,0),1)/INDEX('All Facts'!$F:$F,MATCH(Solver!$B2,'All Facts'!$B:$B,0),1)*$C2 -> 0 | M2: =INDEX('All Facts'!P:P,MATCH(Solver!$B2,'All Facts'!$B:$B,0),1)/INDEX('All Facts'!$F:$F,MATCH(Solver!$B2,'All Facts'!$B:$B,0),1)*$C2 -> 0 | N2: =INDEX('All Facts'!Q:Q,MATCH(Solver!$B2,'All Facts'!$B:$B,0),1)/INDEX('All Facts'!$F:$F,MATCH(Solver!$B2,'All Facts'!$B:$B,0),1)*$C2 -> 20.27027 | O2: =INDEX('All Facts'!R:R,MATCH(Solver!$B2,'All Facts'!$B:$B,0),1)/INDEX('All Facts'!$F:$F,MATCH(Solver!$B2,'All Facts'!$B:$B,0),1)*$C2 -> 1.1148649 | P2: =INDEX('All Facts'!S:S,MATCH(Solver!$B2,'All Facts'!$B:$B,0),1)/INDEX('All Facts'!$F:$F,MATCH(Solver!$B2,'All Facts'!$B:$B,0),1)*$C2 -> 628.37838 | Q2: =INDEX('All Facts'!T:T,MATCH(Solver!$B2,'All Facts'!$B:$B,0),1)/INDEX('All Facts'!$F:$F,MATCH(Solver!$B2,'All Facts'!$B:$B,0),1)*$C2 -> 2.027027 | R2: =INDEX('All Facts'!U:U,MATCH(Solver!$B2,'All Facts'!$B:$B,0),1)/INDEX('All Facts'!$F:$F,MATCH(Solver!$B2,'All Facts'!$B:$B,0),1)*$C2 -> 1.0135135 | S2: =INDEX('All Facts'!V:V,MATCH(Solver!$B2,'All Facts'!$B:$B,0),1)/INDEX('All Facts'!$F:$F,MATCH(Solver!$B2,'All Facts'!$B:$B,0),1)*$C2 -> 26.351351 | T2: =INDEX('All Facts'!W:W,MATCH(Solver!$B2,'All Facts'!$B:$B,0),1)/INDEX('All Facts'!$F:$F,MATCH(Solver!$B2,'All Facts'!$B:$B,0),1)*$C2 -> 0.2027027 | U2: =INDEX('All Facts'!X:X,MATCH(Solver!$B2,'All Facts'!$B:$B,0),1)/INDEX('All Facts'!$F:$F,MATCH(Solver!$B2,'All Facts'!$B:$B,0),1)*$C2 -> 0 | V2: =INDEX('All Facts'!Y:Y,MATCH(Solver!$B2,'All Facts'!$B:$B,0),1)/INDEX('All Facts'!$F:$F,MATCH(Solver!$B2,'All Facts'!$B:$B,0),1)*$C2 -> 0 | W2: =INDEX('All Facts'!Z:Z,MATCH(Solver!$B2,'All Facts'!$B:$B,0),1)/INDEX('All Facts'!$F:$F,MATCH(Solver!$B2,'All Facts'!$B:$B,0),1)*$C2 -> 0 | AA2: 1 | AB2: 5.798092 | AC2: =INDEX('All Facts'!G:G,MATCH(Solver!$Z$1,'All Facts'!$B:$B,0),1)/INDEX('All Facts'!$F:$F,MATCH(Solver!$Z$1,'All Facts'!$B:$B,0),1)*$AB2 -> 22.778218 | AD2: =INDEX('All Facts'!H:H,MATCH(Solver!$Z$1,'All Facts'!$B:$B,0),1)/INDEX('All Facts'!$F:$F,MATCH(Solver!$Z$1,'All Facts'!$B:$B,0),1)*$AB2 -> 1.8636724 | AE2: =INDEX('All Facts'!I:I,MATCH(Solver!$Z$1,'All Facts'!$B:$B,0),1)/INDEX('All Facts'!$F:$F,MATCH(Solver!$Z$1,'All Facts'!$B:$B,0),1)*$AB2 -> 0.20707471 | AF2: =INDEX('All Facts'!J:J,MATCH(Solver!$Z$1,'All Facts'!$B:$B,0),1)/INDEX('All Facts'!$F:$F,MATCH(Solver!$Z$1,'All Facts'!$B:$B,0),1)*$AB2 -> 1.449523 | AG2: =INDEX('All Facts'!K:K,MATCH(Solver!$Z$1,'All Facts'!$B:$B,0),1)/INDEX('All Facts'!$F:$F,MATCH(Solver!$Z$1,'All Facts'!$B:$B,0),1)*$AB2 -> 1.0353736 | AH2: =INDEX('All Facts'!L:L,MATCH(Solver!$Z$1,'All Facts'!$B:$B,0),1)/INDEX('All Facts'!$F:$F,MATCH(Solver!$Z$1,'All Facts'!$B:$B,0),1)*$AB2 -> 0 | AI2: =INDEX('All Facts'!M:M,MATCH(Solver!$Z$1,'All Facts'!$B:$B,0),1)/INDEX('All Facts'!$F:$F,MATCH(Solver!$Z$1,'All Facts'!$B:$B,0),1)*$AB2 -> 0 | AJ2: =INDEX('All Facts'!N:N,MATCH(Solver!$Z$1,'All Facts'!$B:$B,0),1)/INDEX('All Facts'!$F:$F,MATCH(Solver!$Z$1,'All Facts'!$B:$B,0),1)*$AB2 -> 6.2122414 | AK2: =INDEX('All Facts'!O:O,MATCH(Solver!$Z$1,'All Facts'!$B:$B,0),1)/INDEX('All Facts'!$F:$F,MATCH(Solver!$Z$1,'All Facts'!$B:$B,0),1)*$AB2 -> 35.202701 | AL2: =INDEX('All Facts'!P:P,MATCH(Solver!$Z$1,'All Facts'!$B:$B,0),1)/INDEX('All Facts'!$F:$F,MATCH(Solver!$Z$1,'All Facts'!$B:$B,0),1)*$AB2 -> 0.041414943 | AM2: =INDEX('All Facts'!Q:Q,MATCH(Solver!$Z$1,'All Facts'!$B:$B,0),1)/INDEX('All Facts'!$F:$F,MATCH(Solver!$Z$1,'All Facts'!$B:$B,0),1)*$AB2 -> 41.414943 | AN2: =INDEX('All Facts'!R:R,MATCH(Solver!$Z$1,'All Facts'!$B:$B,0),1)/INDEX('All Facts'!$F:$F,MATCH(Solver!$Z$1,'All Facts'!$B:$B,0),1)*$AB2 -> 0.041414943 | AO2: =INDEX('All Facts'!S:S,MATCH(Solver!$Z$1,'All Facts'!$B:$B,0),1)/INDEX('All Facts'!$F:$F,MATCH(Solver!$Z$1,'All Facts'!$B:$B,0),1)*$AB2 -> 6.2122414 | AP2: =INDEX('All Facts'!T:T,MATCH(Solver!$Z$1,'All Facts'!$B:$B,0),1)/INDEX('All Facts'!$F:$F,MATCH(Solver!$Z$1,'All Facts'!$B:$B,0),1)*$AB2 -> 0 | AQ2: =INDEX('All Facts'!U:U,MATCH(Solver!$Z$1,'All Facts'!$B:$B,0),1)/INDEX('All Facts'!$F:$F,MATCH(Solver!$Z$1,'All Facts'!$B:$B,0),1)*$AB2 -> 0 | AR2: =INDEX('All Facts'!V:V,MATCH(Solver!$Z$1,'All Facts'!$B:$B,0),1)/INDEX('All Facts'!$F:$F,MATCH(Solver!$Z$1,'All Facts'!$B:$B,0),1)*$AB2 -> 0 | AS2: =INDEX('All Facts'!W:W,MATCH(Solver!$Z$1,'All Facts'!$B:$B,0),1)/INDEX('All Facts'!$F:$F,MATCH(Solver!$Z$1,'All Facts'!$B:$B,0),1)*$AB2 -> 0 | AT2: =INDEX('All Facts'!X:X,MATCH(Solver!$Z$1,'All Facts'!$B:$B,0),1)/INDEX('All Facts'!$F:$F,MATCH(Solver!$Z$1,'All Facts'!$B:$B,0),1)*$AB2 -> 0 | AU2: =INDEX('All Facts'!Y:Y,MATCH(Solver!$Z$1,'All Facts'!$B:$B,0),1)/INDEX('All Facts'!$F:$F,MATCH(Solver!$Z$1,'All Facts'!$B:$B,0),1)*$AB2 -> 0 | AV2: =INDEX('All Facts'!Z:Z,MATCH(Solver!$Z$1,'All Facts'!$B:$B,0),1)/INDEX('All Facts'!$F:$F,MATCH(Solver!$Z$1,'All Facts'!$B:$B,0),1)*$AB2 -> 0 | AW2: =ROUNDDOWN(6/28*Solver!AB2,0) -> 1
B3: Peanut Butter | C3: 60 | D3: =INDEX('All Facts'!G:G,MATCH(Solver!$B3,'All Facts'!$B:$B,0),1)/INDEX('All Facts'!$F:$F,MATCH(Solver!$B3,'All Facts'!$B:$B,0),1)*$C3 -> 337.5 | E3: =INDEX('All Facts'!H:H,MATCH(Solver!$B3,'All Facts'!$B:$B,0),1)/INDEX('All Facts'!$F:$F,MATCH(Solver!$B3,'All Facts'!$B:$B,0),1)*$C3 -> 28.125 | F3: =INDEX('All Facts'!I:I,MATCH(Solver!$B3,'All Facts'!$B:$B,0),1)/INDEX('All Facts'!$F:$F,MATCH(Solver!$B3,'All Facts'!$B:$B,0),1)*$C3 -> 13.125 | G3: =INDEX('All Facts'!J:J,MATCH(Solver!$B3,'All Facts'!$B:$B,0),1)/INDEX('All Facts'!$F:$F,MATCH(Solver!$B3,'All Facts'!$B:$B,0),1)*$C3 -> 13.125 | H3: =INDEX('All Facts'!K:K,MATCH(Solver!$B3,'All Facts'!$B:$B,0),1)/INDEX('All Facts'!$F:$F,MATCH(Solver!$B3,'All Facts'!$B:$B,0),1)*$C3 -> 4.6875 | I3: =INDEX('All Facts'!L:L,MATCH(Solver!$B3,'All Facts'!$B:$B,0),1)/INDEX('All Facts'!$F:$F,MATCH(Solver!$B3,'All Facts'!$B:$B,0),1)*$C3 -> 0 | J3: =INDEX('All Facts'!M:M,MATCH(Solver!$B3,'All Facts'!$B:$B,0),1)/INDEX('All Facts'!$F:$F,MATCH(Solver!$B3,'All Facts'!$B:$B,0),1)*$C3 -> 0 | K3: =INDEX('All Facts'!N:N,MATCH(Solver!$B3,'All Facts'!$B:$B,0),1)/INDEX('All Facts'!$F:$F,MATCH(Solver!$B3,'All Facts'!$B:$B,0),1)*$C3 -> 0 | L3: =INDEX('All Facts'!O:O,MATCH(Solver!$B3,'All Facts'!$B:$B,0),1)/INDEX('All Facts'!$F:$F,MATCH(Solver!$B3,'All Facts'!$B:$B,0),1)*$C3 -> 281.25 | M3: =INDEX('All Facts'!P:P,MATCH(Solver!$B3,'All Facts'!$B:$B,0),1)/INDEX('All Facts'!$F:$F,MATCH(Solver!$B3,'All Facts'!$B:$B,0),1)*$C3 -> 0 | N3: =INDEX('All Facts'!Q:Q,MATCH(Solver!$B3,'All Facts'!$B:$B,0),1)/INDEX('All Facts'!$F:$F,MATCH(Solver!$B3,'All Facts'!$B:$B,0),1)*$C3 -> 56.25 | O3: =INDEX('All Facts'!R:R,MATCH(Solver!$B3,'All Facts'!$B:$B,0),1)/INDEX('All Facts'!$F:$F,MATCH(Solver!$B3,'All Facts'!$B:$B,0),1)*$C3 -> 1.875 | P3: =INDEX('All Facts'!S:S,MATCH(Solver!$B3,'All Facts'!$B:$B,0),1)/INDEX('All Facts'!$F:$F,MATCH(Solver!$B3,'All Facts'!$B:$B,0),1)*$C3 -> 393.75 | Q3: =INDEX('All Facts'!T:T,MATCH(Solver!$B3,'All Facts'!$B:$B,0),1)/INDEX('All Facts'!$F:$F,MATCH(Solver!$B3,'All Facts'!$B:$B,0),1)*$C3 -> 3.75 | R3: =INDEX('All Facts'!U:U,MATCH(Solver!$B3,'All Facts'!$B:$B,0),1)/INDEX('All Facts'!$F:$F,MATCH(Solver!$B3,'All Facts'!$B:$B,0),1)*$C3 -> 7.5 | S3: =INDEX('All Facts'!V:V,MATCH(Solver!$B3,'All Facts'!$B:$B,0),1)/INDEX('All Facts'!$F:$F,MATCH(Solver!$B3,'All Facts'!$B:$B,0),1)*$C3 -> 0 | T3: =INDEX('All Facts'!W:W,MATCH(Solver!$B3,'All Facts'!$B:$B,0),1)/INDEX('All Facts'!$F:$F,MATCH(Solver!$B3,'All Facts'!$B:$B,0),1)*$C3 -> 0 | U3: =INDEX('All Facts'!X:X,MATCH(Solver!$B3,'All Facts'!$B:$B,0),1)/INDEX('All Facts'!$F:$F,MATCH(Solver!$B3,'All Facts'!$B:$B,0),1)*$C3 -> 0 | V3: =INDEX('All Facts'!Y:Y,MATCH(Solver!$B3,'All Facts'!$B:$B,0),1)/INDEX('All Facts'!$F:$F,MATCH(Solver!$B3,'All Facts'!$B:$B,0),1)*$C3 -> 0 | W3: =INDEX('All Facts'!Z:Z,MATCH(Solver!$B3,'All Facts'!$B:$B,0),1)/INDEX('All Facts'!$F:$F,MATCH(Solver!$B3,'All Facts'!$B:$B,0),1)*$C3 -> 0 | AA3: 2 | AB3: 1.1985892e-10 | AC3: =INDEX('All Facts'!G:G,MATCH(Solver!$Z$1,'All Facts'!$B:$B,0),1)/INDEX('All Facts'!$F:$F,MATCH(Solver!$Z$1,'All Facts'!$B:$B,0),1)*$AB3 -> 4.7087434e-10 | AD3: =INDEX('All Facts'!H:H,MATCH(Solver!$Z$1,'All Facts'!$B:$B,0),1)/INDEX('All Facts'!$F:$F,MATCH(Solver!$Z$1,'All Facts'!$B:$B,0),1)*$AB3 -> 3.8526082e-11 | AE3: =INDEX('All Facts'!I:I,MATCH(Solver!$Z$1,'All Facts'!$B:$B,0),1)/INDEX('All Facts'!$F:$F,MATCH(Solver!$Z$1,'All Facts'!$B:$B,0),1)*$AB3 -> 4.2806758e-12 | AF3: =INDEX('All Facts'!J:J,MATCH(Solver!$Z$1,'All Facts'!$B:$B,0),1)/INDEX('All Facts'!$F:$F,MATCH(Solver!$Z$1,'All Facts'!$B:$B,0),1)*$AB3 -> 2.9964731e-11 | AG3: =INDEX('All Facts'!K:K,MATCH(Solver!$Z$1,'All Facts'!$B:$B,0),1)/INDEX('All Facts'!$F:$F,MATCH(Solver!$Z$1,'All Facts'!$B:$B,0),1)*$AB3 -> 2.1403379e-11 | AH3: =INDEX('All Facts'!L:L,MATCH(Solver!$Z$1,'All Facts'!$B:$B,0),1)/INDEX('All Facts'!$F:$F,MATCH(Solver!$Z$1,'All Facts'!$B:$B,0),1)*$AB3 -> 0 | AI3: =INDEX('All Facts'!M:M,MATCH(Solver!$Z$1,'All Facts'!$B:$B,0),1)/INDEX('All Facts'!$F:$F,MATCH(Solver!$Z$1,'All Facts'!$B:$B,0),1)*$AB3 -> 0 | AJ3: =INDEX('All Facts'!N:N,MATCH(Solver!$Z$1,'All Facts'!$B:$B,0),1)/INDEX('All Facts'!$F:$F,MATCH(Solver!$Z$1,'All Facts'!$B:$B,0),1)*$AB3 -> 1.2842027e-10 | AK3: =INDEX('All Facts'!O:O,MATCH(Solver!$Z$1,'All Facts'!$B:$B,0),1)/INDEX('All Facts'!$F:$F,MATCH(Solver!$Z$1,'All Facts'!$B:$B,0),1)*$AB3 -> 7.2771489e-10 | AL3: =INDEX('All Facts'!P:P,MATCH(Solver!$Z$1,'All Facts'!$B:$B,0),1)/INDEX('All Facts'!$F:$F,MATCH(Solver!$Z$1,'All Facts'!$B:$B,0),1)*$AB3 -> 8.5613516e-13 | AM3: =INDEX('All Facts'!Q:Q,MATCH(Solver!$Z$1,'All Facts'!$B:$B,0),1)/INDEX('All Facts'!$F:$F,MATCH(Solver!$Z$1,'All Facts'!$B:$B,0),1)*$AB3 -> 8.5613516e-10 | AN3: =INDEX('All Facts'!R:R,MATCH(Solver!$Z$1,'All Facts'!$B:$B,0),1)/INDEX('All Facts'!$F:$F,MATCH(Solver!$Z$1,'All Facts'!$B:$B,0),1)*$AB3 -> 8.5613516e-13 | AO3: =INDEX('All Facts'!S:S,MATCH(Solver!$Z$1,'All Facts'!$B:$B,0),1)/INDEX('All Facts'!$F:$F,MATCH(Solver!$Z$1,'All Facts'!$B:$B,0),1)*$AB3 -> 1.2842027e-10 | AP3: =INDEX('All Facts'!T:T,MATCH(Solver!$Z$1,'All Facts'!$B:$B,0),1)/INDEX('All Facts'!$F:$F,MATCH(Solver!$Z$1,'All Facts'!$B:$B,0),1)*$AB3 -> 0 | AQ3: =INDEX('All Facts'!U:U,MATCH(Solver!$Z$1,'All Facts'!$B:$B,0),1)/INDEX('All Facts'!$F:$F,MATCH(Solver!$Z$1,'All Facts'!$B:$B,0),1)*$AB3 -> 0 | AR3: =INDEX('All Facts'!V:V,MATCH(Solver!$Z$1,'All Facts'!$B:$B,0),1)/INDEX('All Facts'!$F:$F,MATCH(Solver!$Z$1,'All Facts'!$B:$B,0),1)*$AB3 -> 0 | AS3: =INDEX('All Facts'!W:W,MATCH(Solver!$Z$1,'All Facts'!$B:$B,0),1)/INDEX('All Facts'!$F:$F,MATCH(Solver!$Z$1,'All Facts'!$B:$B,0),1)*$AB3 -> 0 | AT3: =INDEX('All Facts'!X:X,MATCH(Solver!$Z$1,'All Facts'!$B:$B,0),1)/INDEX('All Facts'!$F:$F,MATCH(Solver!$Z$1,'All Facts'!$B:$B,0),1)*$AB3 -> 0 | AU3: =INDEX('All Facts'!Y:Y,MATCH(Solver!$Z$1,'All Facts'!$B:$B,0),1)/INDEX('All Facts'!$F:$F,MATCH(Solver!$Z$1,'All Facts'!$B:$B,0),1)*$AB3 -> 0 | AV3: =INDEX('All Facts'!Z:Z,MATCH(Solver!$Z$1,'All Facts'!$B:$B,0),1)/INDEX('All Facts'!$F:$F,MATCH(Solver!$Z$1,'All Facts'!$B:$B,0),1)*$AB3 -> 0 | AW3: =ROUNDDOWN(6/28*Solver!AB3,0) -> 0
